Workbook
Name Check_Status: Checks!$B$26
Name Scenario: Dashboard!$O$2
Name Scn_Idx: Assumptions!$C$47

Sheet Cover
B2: Northlight Analytics Ltd: scenario and budget-vs-actual model
B3: FY 2026/27 (1 Apr 2026 - 31 Mar 2027). A fictional UK B2B analytics-software company; every number is illustrative.
B5: Model status | C5: =Check_Status -> All checks pass
B6: Scenario shown | C6: =Scenario -> Base
B8: Purpose | C8: Plan next year's P&L and cash under three scenarios, track actual performance against the approved budget, and show whether the full-year outlook still meets plan.
B9: How to use | C9: 1) Pick a scenario on the Dashboard (cell O2). 2) Review or change drivers on Assumptions (blue cells only). 3) Paste each month's actuals into Actuals. 4) Read Budget_vs_Actual and the Dashboard. 5) Confirm the Checks sheet says 'All checks pass'.
B10: Sheets | C10: Dashboard: KPIs, charts, scenario table. Assumptions: every driver with its rationale; hiring plan; variance thresholds. Budget_vs_Actual: YTD and full-year outlook variances with status flags. Actuals: monthly actual inputs (Apr-Sep). Budget_Locked: approved budget, hard-coded values. Model_Base / Model_Upside / Model_Downside: the monthly engine (identical layout) for each scenario. Scenarios: full-year side-by-side comparison. ChartData: helper ranges for charts. Checks: integrity tests.
B11: Colour code | C11: Blue text on yellow = input you may change. Black = formula (do not overwrite). Blue on grey = locked value. Green/red numbers = favourable/adverse variance.
B12: Key logic | C12: Customers roll forward monthly (opening + new - churned). Subscription revenue = average customers x ARPA; a price increase applies from the chosen month. Costs scale with customers (hosting, support), new customers (marketing) and headcount (salaries, tools). 80% of revenue is collected in the month billed, 20% the next month. Tax is 25% of positive monthly EBIT, paid the month after. Capex is depreciated straight-line over 36 months.
B13: Variance convention | C13: Variances are favourable (+) or adverse (-) to profit: for income lines actual minus budget; for cost lines budget minus actual. Status flags use the thresholds on Assumptions (amber 2%, red 5% of budget).
B14: Simplifications | C14: No VAT, no balance-sheet statement, no loss carry-forward, no FX or interest, annual rather than monthly price cohorts, and hires start at the beginning of the month. Churn is applied to opening customers only. These are deliberate to keep the model transparent.
B15: Data | C15: Fictional. The 'actuals' for Apr-Sep were generated from a plausible alternative set of drivers (slower sales, higher churn and hosting cost, a delayed hire, a legal-fee overrun) plus +/-1.5% noise. Do not read them as real company results.

Sheet Dashboard
B2: Northlight Analytics: FY 2026/27 budget, scenarios and variance | N2: Scenario | O2: Base
B3: Fictional company, illustrative numbers. Actuals Apr-Sep 2026; forecast Oct-Mar from the selected scenario. | N3: Checks | O3: =Check_Status -> All checks pass
B5: YTD revenue (Apr-Sep) | D5: YTD EBITDA | F5: FY revenue outlook | I5: FY EBITDA outlook | K5: Cash at 31 Mar (outlook) | M5: Customers at 30 Sep
B6: =Budget_vs_Actual!C8 -> 950710 | D6: =Budget_vs_Actual!C21 -> -141808 | F6: =Budget_vs_Actual!I8 -> 2224757.6 | I6: =Budget_vs_Actual!I21 -> -81495.114 | K6: =CHOOSE(Scn_Idx,Model_Base!N47,Model_Upside!N47,Model_Downside!N47) -> 419338.5 | M6: =Budget_vs_Actual!C25 -> 518
B8: =Budget_vs_Actual!E8 -> -0.026390709 | D8: =Budget_vs_Actual!D21 -> -11776.133 | F8: =Budget_vs_Actual!K8 -> -0.011450648 | I8: =Budget_vs_Actual!J21 -> -11776.133 | K8: =INDEX(Model_Base!C4:N4,MATCH(MIN(CHOOSE(Scn_Idx,Model_Base!C47:N47,Model_Upside!C47:N47,Model_Downside!C47:N47)),CHOOSE(Scn_Idx,Model_Base!C47:N47,Model_Upside!C47:N47,Model_Downside!C47:N47),0))&" is the low point" -> Dec-26 is the low point | M8: =Budget_vs_Actual!E25 -> -0.051282051
B10: Scenario comparison: FY 2026/27
B11: Metric | G11: Budget | H11: Base | I11: Upside | J11: Downside
B12: Total revenue | G12: =Scenarios!B5 -> 2250527.6 | H12: =Scenarios!C5 -> 2250527.6 | I12: =Scenarios!D5 -> 2612225.8 | J12: =Scenarios!E5 -> 1825101.5
B13: EBITDA | G13: =Scenarios!B9 -> -69718.981 | H13: =Scenarios!C9 -> -69718.981 | I13: =Scenarios!D9 -> 95848.746 | J13: =Scenarios!E9 -> -389178.69
B14: EBITDA margin % | G14: =Scenarios!B10 -> -0.030978949 | H14: =Scenarios!C10 -> -0.030978949 | I14: =Scenarios!D10 -> 0.036692366 | J14: =Scenarios!E10 -> -0.21323674
B15: Closing customers (Mar) | G15: =Scenarios!B12 -> 680 | H15: =Scenarios!C12 -> 680 | I15: =Scenarios!D12 -> 803 | J15: =Scenarios!E12 -> 532
B16: Closing cash (Mar) | G16: =Scenarios!B15 -> 419338.5 | H16: =Scenarios!C15 -> 419338.5 | I16: =Scenarios!D15 -> 552042.61 | J16: =Scenarios!E15 -> 116066.27
B17: Lowest month-end cash | G17: =Scenarios!B17 -> 403274.24 | H17: =Scenarios!C17 -> 403274.24 | I17: =Scenarios!D17 -> 457726.71 | J17: =Scenarios!E17 -> 116066.27
B19: Runway at March burn rate (months) | G19: n/a | H19: =Scenarios!C19 -> Cash positive | I19: =Scenarios!D19 -> Cash positive | J19: =Scenarios!E19 -> 3.9679929
B52: Reading the dashboard: green = favourable to profit, red = adverse. Change the scenario in O2 to re-forecast Oct-Mar; actuals and the locked budget never change.

Sheet Assumptions
A1: Assumptions
A2: Blue cells on yellow are inputs. Every driver is documented in the rationale column. Upside / Downside link to Base where a driver is shared.
A4: Driver | B4: Unit | C4: Base | D4: Upside | E4: Downside | F4: Live (selected) | G4: Rationale / source (all illustrative)
A5: Customers and pricing
A6: Opening customers (1 Apr) | B6: customers | C6: 420 | D6: =$C6 -> 420 | E6: =$C6 -> 420 | F6: =CHOOSE(Scn_Idx,C6,D6,E6) -> 420 | G6: Starting point of the financial year (illustrative).
A7: New customers in April | B7: customers / month | C7: 28 | D7: 34 | E7: 21 | F7: =CHOOSE(Scn_Idx,C7,D7,E7) -> 28 | G7: Sales pipeline run-rate; Upside assumes a stronger pipeline, Downside a slower sales cycle.
A8: Monthly growth in new customers | B8: % per month | C8: 0.02 | D8: 0.03 | E8: 0.005 | F8: =CHOOSE(Scn_Idx,C8,D8,E8) -> 0.02 | G8: Compounding monthly growth applied to April's new customers.
A9: Monthly churn (share of opening customers) | B9: % per month | C9: 0.018 | D9: 0.014 | E9: 0.026 | F9: =CHOOSE(Scn_Idx,C9,D9,E9) -> 0.018 | G9: About 19% / 15% / 27% annualised churn; typical range for small-business SaaS.
A10: Average revenue per customer per month (ARPA) | B10: GBP / month | C10: 310 | D10: 322 | E10: 295 | F10: =CHOOSE(Scn_Idx,C10,D10,E10) -> 310 | G10: Subscription price mix; Upside includes more premium-plan customers.
A11: Price increase | B11: % | C11: 0.04 | D11: 0.05 | E11: 0.02 | F11: =CHOOSE(Scn_Idx,C11,D11,E11) -> 0.04 | G11: Annual list-price uplift applied to all customers from the month below.
A12: Price increase effective month (1 = Apr) | B12: month number | C12: 7 | D12: =$C12 -> 7 | E12: =$C12 -> 7 | F12: =CHOOSE(Scn_Idx,C12,D12,E12) -> 7 | G12: Effective 1 October.
A13: Onboarding fee per new customer | B13: GBP | C13: 450 | D13: =$C13 -> 450 | E13: =$C13 -> 450 | F13: =CHOOSE(Scn_Idx,C13,D13,E13) -> 450 | G13: One-off implementation fee.
A14: Cost of sales
A15: Hosting cost per average customer | B15: GBP / month | C15: 14 | D15: 14 | E15: 15 | F15: =CHOOSE(Scn_Idx,C15,D15,E15) -> 14 | G15: Cloud infrastructure; Downside assumes cost inflation.
A16: Customer support cost per average customer | B16: GBP / month | C16: 12 | D16: =$C16 -> 12 | E16: =$C16 -> 12 | F16: =CHOOSE(Scn_Idx,C16,D16,E16) -> 12 | G16: Support tooling and outsourced tier-1.
A17: Payment processing fees | B17: % of revenue | C17: 0.015 | D17: =$C17 -> 0.015 | E17: =$C17 -> 0.015 | F17: =CHOOSE(Scn_Idx,C17,D17,E17) -> 0.015 | G17: Card / direct-debit fees.
A18: People and operating costs
A19: Opening headcount | B19: FTE | C19: 24 | D19: =$C19 -> 24 | E19: =$C19 -> 24 | F19: =CHOOSE(Scn_Idx,C19,D19,E19) -> 24 | G19: Hiring plan is set out in the table below.
A20: Average salary | B20: GBP / year | C20: 52000 | D20: =$C20 -> 52000 | E20: =$C20 -> 52000 | F20: =CHOOSE(Scn_Idx,C20,D20,E20) -> 52000 | G20: Blended across roles.
A21: Employer on-costs (NI, pension, benefits) | B21: % of salary | C21: 0.18 | D21: =$C21 -> 0.18 | E21: =$C21 -> 0.18 | F21: =CHOOSE(Scn_Idx,C21,D21,E21) -> 0.18 | G21: Applied to salaries.
A22: Marketing spend per new customer (CAC) | B22: GBP | C22: 620 | D22: 580 | E22: 700 | F22: =CHOOSE(Scn_Idx,C22,D22,E22) -> 620 | G22: Acquisition marketing; Downside = less efficient channels.
A23: Software and tools per head | B23: GBP / FTE / month | C23: 180 | D23: =$C23 -> 180 | E23: =$C23 -> 180 | F23: =CHOOSE(Scn_Idx,C23,D23,E23) -> 180 | G23: Licences, laptops, collaboration tools.
A24: Rent and facilities | B24: GBP / month | C24: 9500 | D24: =$C24 -> 9500 | E24: =$C24 -> 9500 | F24: =CHOOSE(Scn_Idx,C24,D24,E24) -> 9500 | G24: Office lease; fixed.
A25: Professional fees | B25: GBP / month | C25: 4200 | D25: =$C25 -> 4200 | E25: =$C25 -> 4200 | F25: =CHOOSE(Scn_Idx,C25,D25,E25) -> 4200 | G25: Audit, legal, payroll bureau; fixed.
A26: Other G&A | B26: GBP / month | C26: 6000 | D26: =$C26 -> 6000 | E26: =$C26 -> 6000 | F26: =CHOOSE(Scn_Idx,C26,D26,E26) -> 6000 | G26: Insurance, travel, general admin; fixed.
A27: Capital, tax and cash
A28: Capital expenditure | B28: GBP / month | C28: 8000 | D28: =$C28 -> 8000 | E28: =$C28 -> 8000 | F28: =CHOOSE(Scn_Idx,C28,D28,E28) -> 8000 | G28: Equipment and capitalised development.
A29: Depreciation life of new capex | B29: months | C29: 36 | D29: =$C29 -> 36 | E29: =$C29 -> 36 | F29: =CHOOSE(Scn_Idx,C29,D29,E29) -> 36 | G29: Straight line, starting the month after purchase.
A30: Depreciation on existing assets | B30: GBP / month | C30: 4500 | D30: =$C30 -> 4500 | E30: =$C30 -> 4500 | F30: =CHOOSE(Scn_Idx,C30,D30,E30) -> 4500 | G30: Run-off of the opening asset base.
A31: Corporation tax rate | B31: % | C31: 0.25 | D31: =$C31 -> 0.25 | E31: =$C31 -> 0.25 | F31: =CHOOSE(Scn_Idx,C31,D31,E31) -> 0.25 | G31: UK main rate; charged on positive monthly profit only (simplification: no loss relief).
A32: Share of revenue collected in the month billed | B32: % | C32: 0.8 | D32: =$C32 -> 0.8 | E32: =$C32 -> 0.8 | F32: =CHOOSE(Scn_Idx,C32,D32,E32) -> 0.8 | G32: Remainder collected the following month.
A33: Opening cash (1 Apr) | B33: GBP | C33: 620000 | D33: =$C33 -> 620000 | E33: =$C33 -> 620000 | F33: =CHOOSE(Scn_Idx,C33,D33,E33) -> 620000 | G33: Bank balance at start of year.
A34: Opening trade receivables | B34: GBP | C34: 24000 | D34: =$C34 -> 24000 | E34: =$C34 -> 24000 | F34: =CHOOSE(Scn_Idx,C34,D34,E34) -> 24000 | G34: Collected in April.
A35: Opening tax creditor | B35: GBP | C35: 9000 | D35: =$C35 -> 9000 | E35: =$C35 -> 9000 | F35: =CHOOSE(Scn_Idx,C35,D35,E35) -> 9000 | G35: Paid in April.
A37: Hiring plan: new hires starting in each month (FTE)
A38: Scenario | C38: Apr-26 | D38: May-26 | E38: Jun-26 | F38: Jul-26 | G38: Aug-26 | H38: Sep-26 | I38: Oct-26 | J38: Nov-26 | K38: Dec-26 | L38: Jan-27 | M38: Feb-27 | N38: Mar-27
A39: Base case hires | B39: FTE | C39: 0 | D39: 0 | E39: 1 | F39: 0 | G39: 0 | H39: 1 | I39: 0 | J39: 0 | K39: 1 | L39: 0 | M39: 1 | N39: 0
A40: Upside case hires | B40: FTE | C40: 0 | D40: 1 | E40: 1 | F40: 0 | G40: 1 | H40: 1 | I40: 0 | J40: 1 | K40: 1 | L40: 0 | M40: 1 | N40: 0
A41: Downside case hires | B41: FTE | C41: 0 | D41: 0 | E41: 1 | F41: 0 | G41: 0 | H41: 1 | I41: 0 | J41: 0 | K41: 0 | L41: 0 | M41: 0 | N41: 0
A43: Variance reporting thresholds
...

Sheet Budget_vs_Actual
A1: Budget vs actual
A2: Variances are shown as favourable (+) / adverse (-) to profit. Outlook = YTD actual + forecast for the remaining months from the scenario selected on the Dashboard.
A3: Scenario used for the outlook: | C3: =Scenario -> Base
A5: Line | B5: YTD budget | C5: YTD actual | D5: YTD var £ (F/A) | E5: YTD var % | F5: Status | G5: FY budget | H5: Forecast Oct-Mar | I5: FY outlook | J5: Outlook var £ (F/A) | K5: Outlook var %
A6: Subscription revenue | B6: =SUM(Budget_Locked!C14:H14) -> 896830 | C6: =Actuals!I10 -> 880629 | D6: =C6-B6 -> -16201 | E6: =IFERROR(D6/ABS(B6),0) -> -0.018064739 | F6: =IF(E6>=0,"Favourable",IF(E6>=-Assumptions!$C$44,"On track",IF(E6>=-Assumptions!$C$45,"Watch","Off track"))) -> On track | G6: =Budget_Locked!O14 -> 2081327.6 | H6: =CHOOSE(Scn_Idx,SUM(Model_Base!I14:N14),SUM(Model_Upside!I14:N14),SUM(Model_Downside!I14:N14)) -> 1184497.6 | I6: =C6+H6 -> 2065126.6 | J6: =I6-G6 -> -16201 | K6: =IFERROR(J6/ABS(G6),0) -> -0.007783974
A7: Onboarding revenue | B7: =SUM(Budget_Locked!C15:H15) -> 79650 | C7: =Actuals!I11 -> 70081 | D7: =C7-B7 -> -9569 | E7: =IFERROR(D7/ABS(B7),0) -> -0.1201381 | F7: =IF(E7>=0,"Favourable",IF(E7>=-Assumptions!$C$44,"On track",IF(E7>=-Assumptions!$C$45,"Watch","Off track"))) -> Off track | G7: =Budget_Locked!O15 -> 169200 | H7: =CHOOSE(Scn_Idx,SUM(Model_Base!I15:N15),SUM(Model_Upside!I15:N15),SUM(Model_Downside!I15:N15)) -> 89550 | I7: =C7+H7 -> 159631 | J7: =I7-G7 -> -9569 | K7: =IFERROR(J7/ABS(G7),0) -> -0.056554374
A8: Total revenue | B8: =SUM(Budget_Locked!C16:H16) -> 976480 | C8: =Actuals!I12 -> 950710 | D8: =C8-B8 -> -25770 | E8: =IFERROR(D8/ABS(B8),0) -> -0.026390709 | F8: =IF(E8>=0,"Favourable",IF(E8>=-Assumptions!$C$44,"On track",IF(E8>=-Assumptions!$C$45,"Watch","Off track"))) -> Watch | G8: =Budget_Locked!O16 -> 2250527.6 | H8: =CHOOSE(Scn_Idx,SUM(Model_Base!I16:N16),SUM(Model_Upside!I16:N16),SUM(Model_Downside!I16:N16)) -> 1274047.6 | I8: =C8+H8 -> 2224757.6 | J8: =I8-G8 -> -25770 | K8: =IFERROR(J8/ABS(G8),0) -> -0.011450648
A9: Hosting | B9: =SUM(Budget_Locked!C17:H17) -> 40502 | C9: =Actuals!I14 -> 42892 | D9: =B9-C9 -> -2390 | E9: =IFERROR(D9/ABS(B9),0) -> -0.059009432 | F9: =IF(E9>=0,"Favourable",IF(E9>=-Assumptions!$C$44,"On track",IF(E9>=-Assumptions!$C$45,"Watch","Off track"))) -> Off track | G9: =Budget_Locked!O17 -> 91938 | H9: =CHOOSE(Scn_Idx,SUM(Model_Base!I17:N17),SUM(Model_Upside!I17:N17),SUM(Model_Downside!I17:N17)) -> 51436 | I9: =C9+H9 -> 94328 | J9: =G9-I9 -> -2390 | K9: =IFERROR(J9/ABS(G9),0) -> -0.02599578
A10: Customer support | B10: =SUM(Budget_Locked!C18:H18) -> 34716 | C10: =Actuals!I15 -> 33684 | D10: =B10-C10 -> 1032 | E10: =IFERROR(D10/ABS(B10),0) -> 0.029726927 | F10: =IF(E10>=0,"Favourable",IF(E10>=-Assumptions!$C$44,"On track",IF(E10>=-Assumptions!$C$45,"Watch","Off track"))) -> Favourable | G10: =Budget_Locked!O18 -> 78804 | H10: =CHOOSE(Scn_Idx,SUM(Model_Base!I18:N18),SUM(Model_Upside!I18:N18),SUM(Model_Downside!I18:N18)) -> 44088 | I10: =C10+H10 -> 77772 | J10: =G10-I10 -> 1032 | K10: =IFERROR(J10/ABS(G10),0) -> 0.013095782
A11: Payment fees | B11: =SUM(Budget_Locked!C19:H19) -> 14647.2 | C11: =Actuals!I16 -> 14227 | D11: =B11-C11 -> 420.2 | E11: =IFERROR(D11/ABS(B11),0) -> 0.028688077 | F11: =IF(E11>=0,"Favourable",IF(E11>=-Assumptions!$C$44,"On track",IF(E11>=-Assumptions!$C$45,"Watch","Off track"))) -> Favourable | G11: =Budget_Locked!O19 -> 33757.914 | H11: =CHOOSE(Scn_Idx,SUM(Model_Base!I19:N19),SUM(Model_Upside!I19:N19),SUM(Model_Downside!I19:N19)) -> 19110.714 | I11: =C11+H11 -> 33337.714 | J11: =G11-I11 -> 420.2 | K11: =IFERROR(J11/ABS(G11),0) -> 0.012447452
A12: Total cost of sales | B12: =SUM(Budget_Locked!C20:H20) -> 89865.2 | C12: =Actuals!I17 -> 90803 | D12: =B12-C12 -> -937.8 | E12: =IFERROR(D12/ABS(B12),0) -> -0.01043563 | F12: =IF(E12>=0,"Favourable",IF(E12>=-Assumptions!$C$44,"On track",IF(E12>=-Assumptions!$C$45,"Watch","Off track"))) -> On track | G12: =Budget_Locked!O20 -> 204499.91 | H12: =CHOOSE(Scn_Idx,SUM(Model_Base!I20:N20),SUM(Model_Upside!I20:N20),SUM(Model_Downside!I20:N20)) -> 114634.71 | I12: =C12+H12 -> 205437.71 | J12: =G12-I12 -> -937.8 | K12: =IFERROR(J12/ABS(G12),0) -> -0.004585821
A13: Gross profit | B13: =SUM(Budget_Locked!C21:H21) -> 886614.8 | C13: =Actuals!I18 -> 859907 | D13: =C13-B13 -> -26707.8 | E13: =IFERROR(D13/ABS(B13),0) -> -0.030123341 | F13: =IF(E13>=0,"Favourable",IF(E13>=-Assumptions!$C$44,"On track",IF(E13>=-Assumptions!$C$45,"Watch","Off track"))) -> Watch | G13: =Budget_Locked!O21 -> 2046027.7 | H13: =CHOOSE(Scn_Idx,SUM(Model_Base!I21:N21),SUM(Model_Upside!I21:N21),SUM(Model_Downside!I21:N21)) -> 1159412.9 | I13: =C13+H13 -> 2019319.9 | J13: =I13-G13 -> -26707.8 | K13: =IFERROR(J13/ABS(G13),0) -> -0.013053489
A14: Salaries and on-costs | B14: =SUM(Budget_Locked!C26:H26) -> 761886.67 | C14: =Actuals!I20 -> 747330 | D14: =B14-C14 -> 14556.667 | E14: =IFERROR(D14/ABS(B14),0) -> 0.019106079 | F14: =IF(E14>=0,"Favourable",IF(E14>=-Assumptions!$C$44,"On track",IF(E14>=-Assumptions!$C$45,"Watch","Off track"))) -> Favourable | G14: =Budget_Locked!O26 -> 1590246.7 | H14: =CHOOSE(Scn_Idx,SUM(Model_Base!I26:N26),SUM(Model_Upside!I26:N26),SUM(Model_Downside!I26:N26)) -> 828360 | I14: =C14+H14 -> 1575690 | J14: =G14-I14 -> 14556.667 | K14: =IFERROR(J14/ABS(G14),0) -> 0.0091537162
A15: Marketing | B15: =SUM(Budget_Locked!C27:H27) -> 109740 | C15: =Actuals!I21 -> 102720 | D15: =B15-C15 -> 7020 | E15: =IFERROR(D15/ABS(B15),0) -> 0.063969382 | F15: =IF(E15>=0,"Favourable",IF(E15>=-Assumptions!$C$44,"On track",IF(E15>=-Assumptions!$C$45,"Watch","Off track"))) -> Favourable | G15: =Budget_Locked!O27 -> 233120 | H15: =CHOOSE(Scn_Idx,SUM(Model_Base!I27:N27),SUM(Model_Upside!I27:N27),SUM(Model_Downside!I27:N27)) -> 123380 | I15: =C15+H15 -> 226100 | J15: =G15-I15 -> 7020 | K15: =IFERROR(J15/ABS(G15),0) -> 0.030113246
A16: Software and tools | B16: =SUM(Budget_Locked!C28:H28) -> 26820 | C16: =Actuals!I22 -> 27539 | D16: =B16-C16 -> -719 | E16: =IFERROR(D16/ABS(B16),0) -> -0.026808352 | F16: =IF(E16>=0,"Favourable",IF(E16>=-Assumptions!$C$44,"On track",IF(E16>=-Assumptions!$C$45,"Watch","Off track"))) -> Watch | G16: =Budget_Locked!O28 -> 55980 | H16: =CHOOSE(Scn_Idx,SUM(Model_Base!I28:N28),SUM(Model_Upside!I28:N28),SUM(Model_Downside!I28:N28)) -> 29160 | I16: =C16+H16 -> 56699 | J16: =G16-I16 -> -719 | K16: =IFERROR(J16/ABS(G16),0) -> -0.012843873
A17: Rent and facilities | B17: =SUM(Budget_Locked!C29:H29) -> 57000 | C17: =Actuals!I23 -> 56938 | D17: =B17-C17 -> 62 | E17: =IFERROR(D17/ABS(B17),0) -> 0.0010877193 | F17: =IF(E17>=0,"Favourable",IF(E17>=-Assumptions!$C$44,"On track",IF(E17>=-Assumptions!$C$45,"Watch","Off track"))) -> Favourable | G17: =Budget_Locked!O29 -> 114000 | H17: =CHOOSE(Scn_Idx,SUM(Model_Base!I29:N29),SUM(Model_Upside!I29:N29),SUM(Model_Downside!I29:N29)) -> 57000 | I17: =C17+H17 -> 113938 | J17: =G17-I17 -> 62 | K17: =IFERROR(J17/ABS(G17),0) -> 0.00054385965
A18: Professional fees | B18: =SUM(Budget_Locked!C30:H30) -> 25200 | C18: =Actuals!I24 -> 29435 | D18: =B18-C18 -> -4235 | E18: =IFERROR(D18/ABS(B18),0) -> -0.16805556 | F18: =IF(E18>=0,"Favourable",IF(E18>=-Assumptions!$C$44,"On track",IF(E18>=-Assumptions!$C$45,"Watch","Off track"))) -> Off track | G18: =Budget_Locked!O30 -> 50400 | H18: =CHOOSE(Scn_Idx,SUM(Model_Base!I30:N30),SUM(Model_Upside!I30:N30),SUM(Model_Downside!I30:N30)) -> 25200 | I18: =C18+H18 -> 54635 | J18: =G18-I18 -> -4235 | K18: =IFERROR(J18/ABS(G18),0) -> -0.084027778
A19: Other G&A | B19: =SUM(Budget_Locked!C31:H31) -> 36000 | C19: =Actuals!I25 -> 37753 | D19: =B19-C19 -> -1753 | E19: =IFERROR(D19/ABS(B19),0) -> -0.048694444 | F19: =IF(E19>=0,"Favourable",IF(E19>=-Assumptions!$C$44,"On track",IF(E19>=-Assumptions!$C$45,"Watch","Off track"))) -> Watch | G19: =Budget_Locked!O31 -> 72000 | H19: =CHOOSE(Scn_Idx,SUM(Model_Base!I31:N31),SUM(Model_Upside!I31:N31),SUM(Model_Downside!I31:N31)) -> 36000 | I19: =C19+H19 -> 73753 | J19: =G19-I19 -> -1753 | K19: =IFERROR(J19/ABS(G19),0) -> -0.024347222
A20: Total operating expenses | B20: =SUM(Budget_Locked!C32:H32) -> 1016646.7 | C20: =Actuals!I26 -> 1001715 | D20: =B20-C20 -> 14931.667 | E20: =IFERROR(D20/ABS(B20),0) -> 0.014687174 | F20: =IF(E20>=0,"Favourable",IF(E20>=-Assumptions!$C$44,"On track",IF(E20>=-Assumptions!$C$45,"Watch","Off track"))) -> Favourable | G20: =Budget_Locked!O32 -> 2115746.7 | H20: =CHOOSE(Scn_Idx,SUM(Model_Base!I32:N32),SUM(Model_Upside!I32:N32),SUM(Model_Downside!I32:N32)) -> 1099100 | I20: =C20+H20 -> 2100815 | J20: =G20-I20 -> 14931.667 | K20: =IFERROR(J20/ABS(G20),0) -> 0.0070573982
A21: EBITDA | B21: =SUM(Budget_Locked!C33:H33) -> -130031.87 | C21: =Actuals!I27 -> -141808 | D21: =C21-B21 -> -11776.133 | E21: =IFERROR(D21/ABS(B21),0) -> -0.090563441 | F21: =IF(E21>=0,"Favourable",IF(E21>=-Assumptions!$C$44,"On track",IF(E21>=-Assumptions!$C$45,"Watch","Off track"))) -> Off track | G21: =Budget_Locked!O33 -> -69718.981 | H21: =CHOOSE(Scn_Idx,SUM(Model_Base!I33:N33),SUM(Model_Upside!I33:N33),SUM(Model_Downside!I33:N33)) -> 60312.886 | I21: =C21+H21 -> -81495.114 | J21: =I21-G21 -> -11776.133 | K21: =IFERROR(J21/ABS(G21),0) -> -0.16890857
A23: Key operating metrics at 30 September
A24: Metric | B24: Budget | C24: Actual | D24: Var (F/A) | E24: Var %
A25: Closing customers | B25: =Budget_Locked!H10 -> 546 | C25: =Actuals!H8 -> 518 | D25: =C25-B25 -> -28 | E25: =IFERROR(D25/ABS(B25),0) -> -0.051282051
A26: Closing cash (£) | B26: =Budget_Locked!H47 -> 421008.13 | C26: =Actuals!H29 -> 403562 | D26: =C26-B26 -> -17446.133 | E26: =IFERROR(D26/ABS(B26),0) -> -0.041438946
A27: Total new customers Apr-Sep | B27: =SUM(Budget_Locked!C8:H8) -> 177 | C27: =Actuals!I6 -> 156 | D27: =C27-B27 -> -21 | E27: =IFERROR(D27/ABS(B27),0) -> -0.11864407
A28: Total churned customers Apr-Sep (lower is better) | B28: =SUM(Budget_Locked!C9:H9) -> 51 | C28: =Actuals!I7 -> 58 | D28: =B28-C28 -> -7 | E28: =IFERROR(D28/ABS(B28),0) -> -0.1372549

Sheet Actuals
A1: Actuals: April to September 2026
A2: Illustrative, fictional figures. Replace the blue inputs each month; everything else updates. Totals are formulas.
A4: £ unless stated | B4: Unit | C4: Apr-26 | D4: May-26 | E4: Jun-26 | F4: Jul-26 | G4: Aug-26 | H4: Sep-26 | I4: YTD
A5: CUSTOMERS
A6: New customers | B6: customers | C6: 25 | D6: 25 | E6: 26 | F6: 26 | G6: 27 | H6: 27 | I6: =SUM(C6:H6) -> 156
A7: Churned customers | B7: customers | C7: 9 | D7: 9 | E7: 9 | F7: 10 | G7: 10 | H7: 11 | I7: =SUM(C7:H7) -> 58
A8: Closing customers | B8: customers | C8: 436 | D8: 452 | E8: 469 | F8: 485 | G8: 502 | H8: 518 | I8: =H8 -> 518
A9: REVENUE
A10: Subscription revenue | B10: £ | C10: 134037 | D10: 140179 | E10: 144864 | F10: 147597 | G10: 153049 | H10: 160903 | I10: =SUM(C10:H10) -> 880629
A11: Onboarding revenue | B11: £ | C11: 11083 | D11: 11358 | E11: 11804 | F11: 11689 | G11: 12078 | H11: 12069 | I11: =SUM(C11:H11) -> 70081
A12: Total revenue | B12: £ | C12: =C10+C11 -> 145120 | D12: =D10+D11 -> 151537 | E12: =E10+E11 -> 156668 | F12: =F10+F11 -> 159286 | G12: =G10+G11 -> 165127 | H12: =H10+H11 -> 172972 | I12: =SUM(C12:H12) -> 950710
A13: COST OF SALES
A14: Hosting | B14: £ | C14: 6458 | D14: 6738 | E14: 7001 | F14: 7262 | G14: 7613 | H14: 7820 | I14: =SUM(C14:H14) -> 42892
A15: Customer support | B15: £ | C15: 5155 | D15: 5406 | E15: 5479 | F15: 5666 | G15: 5942 | H15: 6036 | I15: =SUM(C15:H15) -> 33684
A16: Payment fees | B16: £ | C16: 2142 | D16: 2248 | E16: 2328 | F16: 2438 | G16: 2501 | H16: 2570 | I16: =SUM(C16:H16) -> 14227
A17: Total cost of sales | B17: £ | C17: =C14+C15+C16 -> 13755 | D17: =D14+D15+D16 -> 14392 | E17: =E14+E15+E16 -> 14808 | F17: =F14+F15+F16 -> 15366 | G17: =G14+G15+G16 -> 16056 | H17: =H14+H15+H16 -> 16426 | I17: =SUM(C17:H17) -> 90803
A18: Gross profit | B18: £ | C18: =C12-C17 -> 131365 | D18: =D12-D17 -> 137145 | E18: =E12-E17 -> 141860 | F18: =F12-F17 -> 143920 | G18: =G12-G17 -> 149071 | H18: =H12-H17 -> 156546 | I18: =SUM(C18:H18) -> 859907
A19: OPERATING EXPENSES
A20: Salaries and on-costs | B20: £ | C20: 122708 | D20: 121790 | E20: 120923 | F20: 126654 | G20: 128570 | H20: 126685 | I20: =SUM(C20:H20) -> 747330
A21: Marketing | B21: £ | C21: 16435 | D21: 16254 | E21: 17330 | F21: 16982 | G21: 17696 | H21: 18023 | I21: =SUM(C21:H21) -> 102720
A22: Software and tools | B22: £ | C22: 4489 | D22: 4535 | E22: 4507 | F22: 4709 | G22: 4618 | H22: 4681 | I22: =SUM(C22:H22) -> 27539
A23: Rent and facilities | B23: £ | C23: 9502 | D23: 9606 | E23: 9460 | F23: 9528 | G23: 9374 | H23: 9468 | I23: =SUM(C23:H23) -> 56938
A24: Professional fees | B24: £ | C24: 4874 | D24: 4849 | E24: 4947 | F24: 4882 | G24: 4970 | H24: 4913 | I24: =SUM(C24:H24) -> 29435
A25: Other G&A | B25: £ | C25: 6320 | D25: 6326 | E25: 6333 | F25: 6234 | G25: 6289 | H25: 6251 | I25: =SUM(C25:H25) -> 37753
A26: Total operating expenses | B26: £ | C26: =SUM(C20:C25) -> 164328 | D26: =SUM(D20:D25) -> 163360 | E26: =SUM(E20:E25) -> 163500 | F26: =SUM(F20:F25) -> 168989 | G26: =SUM(G20:G25) -> 171517 | H26: =SUM(H20:H25) -> 170021 | I26: =SUM(C26:H26) -> 1001715
A27: EBITDA | B27: £ | C27: =C18-C26 -> -32963 | D27: =D18-D26 -> -26215 | E27: =E18-E26 -> -21640 | F27: =F18-F26 -> -25069 | G27: =G18-G26 -> -22446 | H27: =H18-H26 -> -13475 | I27: =SUM(C27:H27) -> -141808
A28: CASH
A29: Closing cash (bank) | B29: £ | C29: 564607 | D29: 526656 | E29: 492988 | F29: 458732 | G29: 428791 | H29: 403562 | I29: =H29 -> 403562

Sheet Budget_Locked
A1: Approved budget (locked values)
A2: Hard-coded copy of the Base case at budget approval (1 Apr 2026). It does NOT move when Assumptions change: variances are always measured against this.
A4: £ unless stated | B4: Unit | C4: Apr-26 | D4: May-26 | E4: Jun-26 | F4: Jul-26 | G4: Aug-26 | H4: Sep-26 | I4: Oct-26 | J4: Nov-26 | K4: Dec-26 | L4: Jan-27 | M4: Feb-27 | N4: Mar-27 | O4: FY 2026/27 | Q4: Lock note
A5: CUSTOMERS | Q5: Grey cells are values, not formulas. To re-baseline the budget, copy Model_Base and paste as values here.
A6: Month number | B6: # | C6: 1 | D6: 2 | E6: 3 | F6: 4 | G6: 5 | H6: 6 | I6: 7 | J6: 8 | K6: 9 | L6: 10 | M6: 11 | N6: 12
A7: Opening customers | B7: customers | C7: 420 | D7: 440 | E7: 461 | F7: 482 | G7: 503 | H7: 524 | I7: 546 | J7: 568 | K7: 590 | L7: 612 | M7: 634 | N7: 657 | O7: =C7 -> 420
A8: New customers | B8: customers | C8: 28 | D8: 29 | E8: 29 | F8: 30 | G8: 30 | H8: 31 | I8: 32 | J8: 32 | K8: 33 | L8: 33 | M8: 34 | N8: 35 | O8: =SUM(C8:N8) -> 376
A9: Churned customers | B9: customers | C9: 8 | D9: 8 | E9: 8 | F9: 9 | G9: 9 | H9: 9 | I9: 10 | J9: 10 | K9: 11 | L9: 11 | M9: 11 | N9: 12 | O9: =SUM(C9:N9) -> 116
A10: Closing customers | B10: customers | C10: 440 | D10: 461 | E10: 482 | F10: 503 | G10: 524 | H10: 546 | I10: 568 | J10: 590 | K10: 612 | L10: 634 | M10: 657 | N10: 680 | O10: =N10 -> 680
A11: Average customers | B11: customers | C11: 430 | D11: 450.5 | E11: 471.5 | F11: 492.5 | G11: 513.5 | H11: 535 | I11: 557 | J11: 579 | K11: 601 | L11: 623 | M11: 645.5 | N11: 668.5 | O11: =AVERAGE(C11:N11) -> 547.25
A12: ARPA (after price increase) | B12: £ / month | C12: 310 | D12: 310 | E12: 310 | F12: 310 | G12: 310 | H12: 310 | I12: 322.4 | J12: 322.4 | K12: 322.4 | L12: 322.4 | M12: 322.4 | N12: 322.4 | O12: =AVERAGE(C12:N12) -> 316.2
A13: PROFIT AND LOSS
A14: Subscription revenue | B14: £ | C14: 133300 | D14: 139655 | E14: 146165 | F14: 152675 | G14: 159185 | H14: 165850 | I14: 179576.8 | J14: 186669.6 | K14: 193762.4 | L14: 200855.2 | M14: 208109.2 | N14: 215524.4 | O14: =SUM(C14:N14) -> 2081327.6
A15: Onboarding revenue | B15: £ | C15: 12600 | D15: 13050 | E15: 13050 | F15: 13500 | G15: 13500 | H15: 13950 | I15: 14400 | J15: 14400 | K15: 14850 | L15: 14850 | M15: 15300 | N15: 15750 | O15: =SUM(C15:N15) -> 169200
A16: Total revenue | B16: £ | C16: 145900 | D16: 152705 | E16: 159215 | F16: 166175 | G16: 172685 | H16: 179800 | I16: 193976.8 | J16: 201069.6 | K16: 208612.4 | L16: 215705.2 | M16: 223409.2 | N16: 231274.4 | O16: =SUM(C16:N16) -> 2250527.6
A17: Hosting | B17: £ | C17: 6020 | D17: 6307 | E17: 6601 | F17: 6895 | G17: 7189 | H17: 7490 | I17: 7798 | J17: 8106 | K17: 8414 | L17: 8722 | M17: 9037 | N17: 9359 | O17: =SUM(C17:N17) -> 91938
A18: Customer support | B18: £ | C18: 5160 | D18: 5406 | E18: 5658 | F18: 5910 | G18: 6162 | H18: 6420 | I18: 6684 | J18: 6948 | K18: 7212 | L18: 7476 | M18: 7746 | N18: 8022 | O18: =SUM(C18:N18) -> 78804
A19: Payment fees | B19: £ | C19: 2188.5 | D19: 2290.575 | E19: 2388.225 | F19: 2492.625 | G19: 2590.275 | H19: 2697 | I19: 2909.652 | J19: 3016.044 | K19: 3129.186 | L19: 3235.578 | M19: 3351.138 | N19: 3469.116 | O19: =SUM(C19:N19) -> 33757.914
A20: Total cost of sales | B20: £ | C20: 13368.5 | D20: 14003.575 | E20: 14647.225 | F20: 15297.625 | G20: 15941.275 | H20: 16607 | I20: 17391.652 | J20: 18070.044 | K20: 18755.186 | L20: 19433.578 | M20: 20134.138 | N20: 20850.116 | O20: =SUM(C20:N20) -> 204499.91
A21: Gross profit | B21: £ | C21: 132531.5 | D21: 138701.42 | E21: 144567.77 | F21: 150877.38 | G21: 156743.73 | H21: 163193 | I21: 176585.15 | J21: 182999.56 | K21: 189857.21 | L21: 196271.62 | M21: 203275.06 | N21: 210424.28 | O21: =SUM(C21:N21) -> 2046027.7
A22: Gross margin % | B22: % | C22: 0.90837217 | D22: 0.90829655 | E22: 0.90800349 | F22: 0.90794268 | G22: 0.90768582 | H22: 0.90763626 | I22: 0.91034159 | J22: 0.9101304 | K22: 0.91009554 | L22: 0.90990677 | M22: 0.90987776 | N22: 0.90984685 | O22: =IFERROR(O21/O16,0) -> 0.90913246
A23: Opening headcount | B23: FTE | C23: 24 | D23: 24 | E23: 24 | F23: 25 | G23: 25 | H23: 25 | I23: 26 | J23: 26 | K23: 26 | L23: 27 | M23: 27 | N23: 28 | O23: =C23 -> 24
A24: New hires | B24: FTE | C24: 0 | D24: 0 | E24: 1 | F24: 0 | G24: 0 | H24: 1 | I24: 0 | J24: 0 | K24: 1 | L24: 0 | M24: 1 | N24: 0 | O24: =SUM(C24:N24) -> 4
A25: Closing headcount | B25: FTE | C25: 24 | D25: 24 | E25: 25 | F25: 25 | G25: 25 | H25: 26 | I25: 26 | J25: 26 | K25: 27 | L25: 27 | M25: 28 | N25: 28 | O25: =N25 -> 28
A26: Salaries and on-costs | B26: £ | C26: 122720 | D26: 122720 | E26: 127833.33 | F26: 127833.33 | G26: 127833.33 | H26: 132946.67 | I26: 132946.67 | J26: 132946.67 | K26: 138060 | L26: 138060 | M26: 143173.33 | N26: 143173.33 | O26: =SUM(C26:N26) -> 1590246.7
A27: Marketing (CAC x new customers) | B27: £ | C27: 17360 | D27: 17980 | E27: 17980 | F27: 18600 | G27: 18600 | H27: 19220 | I27: 19840 | J27: 19840 | K27: 20460 | L27: 20460 | M27: 21080 | N27: 21700 | O27: =SUM(C27:N27) -> 233120
A28: Software and tools | B28: £ | C28: 4320 | D28: 4320 | E28: 4500 | F28: 4500 | G28: 4500 | H28: 4680 | I28: 4680 | J28: 4680 | K28: 4860 | L28: 4860 | M28: 5040 | N28: 5040 | O28: =SUM(C28:N28) -> 55980
A29: Rent and facilities | B29: £ | C29: 9500 | D29: 9500 | E29: 9500 | F29: 9500 | G29: 9500 | H29: 9500 | I29: 9500 | J29: 9500 | K29: 9500 | L29: 9500 | M29: 9500 | N29: 9500 | O29: =SUM(C29:N29) -> 114000
A30: Professional fees | B30: £ | C30: 4200 | D30: 4200 | E30: 4200 | F30: 4200 | G30: 4200 | H30: 4200 | I30: 4200 | J30: 4200 | K30: 4200 | L30: 4200 | M30: 4200 | N30: 4200 | O30: =SUM(C30:N30) -> 50400
A31: Other G&A | B31: £ | C31: 6000 | D31: 6000 | E31: 6000 | F31: 6000 | G31: 6000 | H31: 6000 | I31: 6000 | J31: 6000 | K31: 6000 | L31: 6000 | M31: 6000 | N31: 6000 | O31: =SUM(C31:N31) -> 72000
A32: Total operating expenses | B32: £ | C32: 164100 | D32: 164720 | E32: 170013.33 | F32: 170633.33 | G32: 170633.33 | H32: 176546.67 | I32: 177166.67 | J32: 177166.67 | K32: 183080 | L32: 183080 | M32: 188993.33 | N32: 189613.33 | O32: =SUM(C32:N32) -> 2115746.7
A33: EBITDA | B33: £ | C33: -31568.5 | D33: -26018.575 | E33: -25445.558 | F33: -19755.958 | G33: -13889.608 | H33: -13353.667 | I33: -581.51867 | J33: 5832.8893 | K33: 6777.214 | L33: 13191.622 | M33: 14281.729 | N33: 20810.951 | O33: =SUM(C33:N33) -> -69718.981
A34: EBITDA margin % | B34: % | C34: -0.2163708 | D34: -0.17038457 | E34: -0.15981885 | F34: -0.11888647 | G34: -0.080433207 | H34: -0.074269559 | I34: -0.0029978774 | J34: 0.029009305 | K34: 0.03248711 | L34: 0.06115579 | M34: 0.063926323 | N34: 0.089983806 | O34: =IFERROR(O33/O16,0) -> -0.030978949
A35: Depreciation | B35: £ | C35: 4500 | D35: 4722.2222 | E35: 4944.4444 | F35: 5166.6667 | G35: 5388.8889 | H35: 5611.1111 | I35: 5833.3333 | J35: 6055.5556 | K35: 6277.7778 | L35: 6500 | M35: 6722.2222 | N35: 6944.4444 | O35: =SUM(C35:N35) -> 68666.667
A36: EBIT | B36: £ | C36: -36068.5 | D36: -30740.797 | E36: -30390.003 | F36: -24922.625 | G36: -19278.497 | H36: -18964.778 | I36: -6414.852 | J36: -222.66622 | K36: 499.43622 | L36: 6691.622 | M36: 7559.5064 | N36: 13866.506 | O36: =SUM(C36:N36) -> -138385.65
A37: Corporation tax charge | B37: £ | C37: 0 | D37: 0 | E37: 0 | F37: 0 | G37: 0 | H37: 0 | I37: 0 | J37: 0 | K37: 124.85906 | L37: 1672.9055 | M37: 1889.8766 | N37: 3466.6266 | O37: =SUM(C37:N37) -> 7154.2677
A38: Net income | B38: £ | C38: -36068.5 | D38: -30740.797 | E38: -30390.003 | F38: -24922.625 | G38: -19278.497 | H38: -18964.778 | I38: -6414.852 | J38: -222.66622 | K38: 374.57717 | L38: 5018.7165 | M38: 5669.6298 | N38: 10399.88 | O38: =SUM(C38:N38) -> -145539.92
A39: CASH FLOW
A40: Cash received from customers | B40: £ | C40: 140720 | D40: 151344 | E40: 157913 | F40: 164783 | G40: 171383 | H40: 178377 | I40: 191141.44 | J40: 199651.04 | K40: 207103.84 | L40: 214286.64 | M40: 221868.4 | N40: 229701.36 | O40: =SUM(C40:N40) -> 2228272.7
A41: Cost of sales paid | B41: £ | C41: 13368.5 | D41: 14003.575 | E41: 14647.225 | F41: 15297.625 | G41: 15941.275 | H41: 16607 | I41: 17391.652 | J41: 18070.044 | K41: 18755.186 | L41: 19433.578 | M41: 20134.138 | N41: 20850.116 | O41: =SUM(C41:N41) -> 204499.91
...

Sheet Model_Base
A1: Base case: monthly model
A2: Driven by the 'Base' column of Assumptions. Same layout on all three scenario sheets and on Budget_Locked.
A4: £ unless stated | B4: Unit | C4: Apr-26 | D4: May-26 | E4: Jun-26 | F4: Jul-26 | G4: Aug-26 | H4: Sep-26 | I4: Oct-26 | J4: Nov-26 | K4: Dec-26 | L4: Jan-27 | M4: Feb-27 | N4: Mar-27 | O4: FY 2026/27
A5: CUSTOMERS
A6: Month number | B6: # | C6: 1 | D6: 2 | E6: 3 | F6: 4 | G6: 5 | H6: 6 | I6: 7 | J6: 8 | K6: 9 | L6: 10 | M6: 11 | N6: 12
A7: Opening customers | B7: customers | C7: =Assumptions!$C$6 -> 420 | D7: =C10 -> 440 | E7: =D10 -> 461 | F7: =E10 -> 482 | G7: =F10 -> 503 | H7: =G10 -> 524 | I7: =H10 -> 546 | J7: =I10 -> 568 | K7: =J10 -> 590 | ... N7: =M10 -> 657 | O7: =C7 -> 420
A8: New customers | B8: customers | C8: =ROUND(Assumptions!$C$7*(1+Assumptions!$C$8)^(C6-1),0) -> 28 | D8: =ROUND(Assumptions!$C$7*(1+Assumptions!$C$8)^(D6-1),0) -> 29 | E8: =ROUND(Assumptions!$C$7*(1+Assumptions!$C$8)^(E6-1),0) -> 29 | F8: =ROUND(Assumptions!$C$7*(1+Assumptions!$C$8)^(F6-1),0) -> 30 | G8: =ROUND(Assumptions!$C$7*(1+Assumptions!$C$8)^(G6-1),0) -> 30 | H8: =ROUND(Assumptions!$C$7*(1+Assumptions!$C$8)^(H6-1),0) -> 31 | I8: =ROUND(Assumptions!$C$7*(1+Assumptions!$C$8)^(I6-1),0) -> 32 | J8: =ROUND(Assumptions!$C$7*(1+Assumptions!$C$8)^(J6-1),0) -> 32 | ... N8: =ROUND(Assumptions!$C$7*(1+Assumptions!$C$8)^(N6-1),0) -> 35 | O8: =SUM(C8:N8) -> 376
A9: Churned customers | B9: customers | C9: =ROUND(C7*Assumptions!$C$9,0) -> 8 | D9: =ROUND(D7*Assumptions!$C$9,0) -> 8 | E9: =ROUND(E7*Assumptions!$C$9,0) -> 8 | F9: =ROUND(F7*Assumptions!$C$9,0) -> 9 | G9: =ROUND(G7*Assumptions!$C$9,0) -> 9 | H9: =ROUND(H7*Assumptions!$C$9,0) -> 9 | I9: =ROUND(I7*Assumptions!$C$9,0) -> 10 | J9: =ROUND(J7*Assumptions!$C$9,0) -> 10 | ... N9: =ROUND(N7*Assumptions!$C$9,0) -> 12 | O9: =SUM(C9:N9) -> 116
A10: Closing customers | B10: customers | C10: =C7+C8-C9 -> 440 | D10: =D7+D8-D9 -> 461 | E10: =E7+E8-E9 -> 482 | F10: =F7+F8-F9 -> 503 | G10: =G7+G8-G9 -> 524 | H10: =H7+H8-H9 -> 546 | I10: =I7+I8-I9 -> 568 | J10: =J7+J8-J9 -> 590 | ... N10: =N7+N8-N9 -> 680 | O10: =N10 -> 680
A11: Average customers | B11: customers | C11: =(C7+C10)/2 -> 430 | D11: =(D7+D10)/2 -> 450.5 | E11: =(E7+E10)/2 -> 471.5 | F11: =(F7+F10)/2 -> 492.5 | G11: =(G7+G10)/2 -> 513.5 | H11: =(H7+H10)/2 -> 535 | I11: =(I7+I10)/2 -> 557 | J11: =(J7+J10)/2 -> 579 | ... N11: =(N7+N10)/2 -> 668.5 | O11: =AVERAGE(C11:N11) -> 547.25
A12: ARPA (after price increase) | B12: £ / month | C12: =Assumptions!$C$10*IF(C6>=Assumptions!$C$12,1+Assumptions!$C$11,1) -> 310 | D12: =Assumptions!$C$10*IF(D6>=Assumptions!$C$12,1+Assumptions!$C$11,1) -> 310 | E12: =Assumptions!$C$10*IF(E6>=Assumptions!$C$12,1+Assumptions!$C$11,1) -> 310 | F12: =Assumptions!$C$10*IF(F6>=Assumptions!$C$12,1+Assumptions!$C$11,1) -> 310 | G12: =Assumptions!$C$10*IF(G6>=Assumptions!$C$12,1+Assumptions!$C$11,1) -> 310 | H12: =Assumptions!$C$10*IF(H6>=Assumptions!$C$12,1+Assumptions!$C$11,1) -> 310 | I12: =Assumptions!$C$10*IF(I6>=Assumptions!$C$12,1+Assumptions!$C$11,1) -> 322.4 | J12: =Assumptions!$C$10*IF(J6>=Assumptions!$C$12,1+Assumptions!$C$11,1) -> 322.4 | ... N12: =Assumptions!$C$10*IF(N6>=Assumptions!$C$12,1+Assumptions!$C$11,1) -> 322.4 | O12: =AVERAGE(C12:N12) -> 316.2
A13: PROFIT AND LOSS
A14: Subscription revenue | B14: £ | C14: =C11*C12 -> 133300 | D14: =D11*D12 -> 139655 | E14: =E11*E12 -> 146165 | F14: =F11*F12 -> 152675 | G14: =G11*G12 -> 159185 | H14: =H11*H12 -> 165850 | I14: =I11*I12 -> 179576.8 | J14: =J11*J12 -> 186669.6 | ... N14: =N11*N12 -> 215524.4 | O14: =SUM(C14:N14) -> 2081327.6
A15: Onboarding revenue | B15: £ | C15: =C8*Assumptions!$C$13 -> 12600 | D15: =D8*Assumptions!$C$13 -> 13050 | E15: =E8*Assumptions!$C$13 -> 13050 | F15: =F8*Assumptions!$C$13 -> 13500 | G15: =G8*Assumptions!$C$13 -> 13500 | H15: =H8*Assumptions!$C$13 -> 13950 | I15: =I8*Assumptions!$C$13 -> 14400 | J15: =J8*Assumptions!$C$13 -> 14400 | ... N15: =N8*Assumptions!$C$13 -> 15750 | O15: =SUM(C15:N15) -> 169200
A16: Total revenue | B16: £ | C16: =C14+C15 -> 145900 | D16: =D14+D15 -> 152705 | E16: =E14+E15 -> 159215 | F16: =F14+F15 -> 166175 | G16: =G14+G15 -> 172685 | H16: =H14+H15 -> 179800 | I16: =I14+I15 -> 193976.8 | J16: =J14+J15 -> 201069.6 | ... N16: =N14+N15 -> 231274.4 | O16: =SUM(C16:N16) -> 2250527.6
A17: Hosting | B17: £ | C17: =C11*Assumptions!$C$15 -> 6020 | D17: =D11*Assumptions!$C$15 -> 6307 | E17: =E11*Assumptions!$C$15 -> 6601 | F17: =F11*Assumptions!$C$15 -> 6895 | G17: =G11*Assumptions!$C$15 -> 7189 | H17: =H11*Assumptions!$C$15 -> 7490 | I17: =I11*Assumptions!$C$15 -> 7798 | J17: =J11*Assumptions!$C$15 -> 8106 | ... N17: =N11*Assumptions!$C$15 -> 9359 | O17: =SUM(C17:N17) -> 91938
A18: Customer support | B18: £ | C18: =C11*Assumptions!$C$16 -> 5160 | D18: =D11*Assumptions!$C$16 -> 5406 | E18: =E11*Assumptions!$C$16 -> 5658 | F18: =F11*Assumptions!$C$16 -> 5910 | G18: =G11*Assumptions!$C$16 -> 6162 | H18: =H11*Assumptions!$C$16 -> 6420 | I18: =I11*Assumptions!$C$16 -> 6684 | J18: =J11*Assumptions!$C$16 -> 6948 | ... N18: =N11*Assumptions!$C$16 -> 8022 | O18: =SUM(C18:N18) -> 78804
A19: Payment fees | B19: £ | C19: =C16*Assumptions!$C$17 -> 2188.5 | D19: =D16*Assumptions!$C$17 -> 2290.575 | E19: =E16*Assumptions!$C$17 -> 2388.225 | F19: =F16*Assumptions!$C$17 -> 2492.625 | G19: =G16*Assumptions!$C$17 -> 2590.275 | H19: =H16*Assumptions!$C$17 -> 2697 | I19: =I16*Assumptions!$C$17 -> 2909.652 | J19: =J16*Assumptions!$C$17 -> 3016.044 | ... N19: =N16*Assumptions!$C$17 -> 3469.116 | O19: =SUM(C19:N19) -> 33757.914
A20: Total cost of sales | B20: £ | C20: =C17+C18+C19 -> 13368.5 | D20: =D17+D18+D19 -> 14003.575 | E20: =E17+E18+E19 -> 14647.225 | F20: =F17+F18+F19 -> 15297.625 | G20: =G17+G18+G19 -> 15941.275 | H20: =H17+H18+H19 -> 16607 | I20: =I17+I18+I19 -> 17391.652 | J20: =J17+J18+J19 -> 18070.044 | ... N20: =N17+N18+N19 -> 20850.116 | O20: =SUM(C20:N20) -> 204499.91
A21: Gross profit | B21: £ | C21: =C16-C20 -> 132531.5 | D21: =D16-D20 -> 138701.42 | E21: =E16-E20 -> 144567.77 | F21: =F16-F20 -> 150877.38 | G21: =G16-G20 -> 156743.73 | H21: =H16-H20 -> 163193 | I21: =I16-I20 -> 176585.15 | J21: =J16-J20 -> 182999.56 | ... N21: =N16-N20 -> 210424.28 | O21: =SUM(C21:N21) -> 2046027.7
A22: Gross margin % | B22: % | C22: =IFERROR(C21/C16,0) -> 0.90837217 | D22: =IFERROR(D21/D16,0) -> 0.90829655 | E22: =IFERROR(E21/E16,0) -> 0.90800349 | F22: =IFERROR(F21/F16,0) -> 0.90794268 | G22: =IFERROR(G21/G16,0) -> 0.90768582 | H22: =IFERROR(H21/H16,0) -> 0.90763626 | I22: =IFERROR(I21/I16,0) -> 0.91034159 | J22: =IFERROR(J21/J16,0) -> 0.9101304 | ... O22: =IFERROR(O21/O16,0) -> 0.90913246
A23: Opening headcount | B23: FTE | C23: =Assumptions!$C$19 -> 24 | D23: =C25 -> 24 | E23: =D25 -> 24 | F23: =E25 -> 25 | G23: =F25 -> 25 | H23: =G25 -> 25 | I23: =H25 -> 26 | J23: =I25 -> 26 | K23: =J25 -> 26 | ... N23: =M25 -> 28 | O23: =C23 -> 24
A24: New hires | B24: FTE | C24: =Assumptions!C39 -> 0 | D24: =Assumptions!D39 -> 0 | E24: =Assumptions!E39 -> 1 | F24: =Assumptions!F39 -> 0 | G24: =Assumptions!G39 -> 0 | H24: =Assumptions!H39 -> 1 | I24: =Assumptions!I39 -> 0 | J24: =Assumptions!J39 -> 0 | ... N24: =Assumptions!N39 -> 0 | O24: =SUM(C24:N24) -> 4
A25: Closing headcount | B25: FTE | C25: =C23+C24 -> 24 | D25: =D23+D24 -> 24 | E25: =E23+E24 -> 25 | F25: =F23+F24 -> 25 | G25: =G23+G24 -> 25 | H25: =H23+H24 -> 26 | I25: =I23+I24 -> 26 | J25: =J23+J24 -> 26 | ... N25: =N23+N24 -> 28 | O25: =N25 -> 28
A26: Salaries and on-costs | B26: £ | C26: =C25*Assumptions!$C$20/12*(1+Assumptions!$C$21) -> 122720 | D26: =D25*Assumptions!$C$20/12*(1+Assumptions!$C$21) -> 122720 | E26: =E25*Assumptions!$C$20/12*(1+Assumptions!$C$21) -> 127833.33 | F26: =F25*Assumptions!$C$20/12*(1+Assumptions!$C$21) -> 127833.33 | G26: =G25*Assumptions!$C$20/12*(1+Assumptions!$C$21) -> 127833.33 | H26: =H25*Assumptions!$C$20/12*(1+Assumptions!$C$21) -> 132946.67 | I26: =I25*Assumptions!$C$20/12*(1+Assumptions!$C$21) -> 132946.67 | J26: =J25*Assumptions!$C$20/12*(1+Assumptions!$C$21) -> 132946.67 | ... N26: =N25*Assumptions!$C$20/12*(1+Assumptions!$C$21) -> 143173.33 | O26: =SUM(C26:N26) -> 1590246.7
A27: Marketing (CAC x new customers) | B27: £ | C27: =C8*Assumptions!$C$22 -> 17360 | D27: =D8*Assumptions!$C$22 -> 17980 | E27: =E8*Assumptions!$C$22 -> 17980 | F27: =F8*Assumptions!$C$22 -> 18600 | G27: =G8*Assumptions!$C$22 -> 18600 | H27: =H8*Assumptions!$C$22 -> 19220 | I27: =I8*Assumptions!$C$22 -> 19840 | J27: =J8*Assumptions!$C$22 -> 19840 | ... N27: =N8*Assumptions!$C$22 -> 21700 | O27: =SUM(C27:N27) -> 233120
A28: Software and tools | B28: £ | C28: =C25*Assumptions!$C$23 -> 4320 | D28: =D25*Assumptions!$C$23 -> 4320 | E28: =E25*Assumptions!$C$23 -> 4500 | F28: =F25*Assumptions!$C$23 -> 4500 | G28: =G25*Assumptions!$C$23 -> 4500 | H28: =H25*Assumptions!$C$23 -> 4680 | I28: =I25*Assumptions!$C$23 -> 4680 | J28: =J25*Assumptions!$C$23 -> 4680 | ... N28: =N25*Assumptions!$C$23 -> 5040 | O28: =SUM(C28:N28) -> 55980
A29: Rent and facilities | B29: £ | C29: =Assumptions!$C$24 -> 9500 | D29: =Assumptions!$C$24 -> 9500 | E29: =Assumptions!$C$24 -> 9500 | F29: =Assumptions!$C$24 -> 9500 | G29: =Assumptions!$C$24 -> 9500 | H29: =Assumptions!$C$24 -> 9500 | I29: =Assumptions!$C$24 -> 9500 | J29: =Assumptions!$C$24 -> 9500 | ... N29: =Assumptions!$C$24 -> 9500 | O29: =SUM(C29:N29) -> 114000
A30: Professional fees | B30: £ | C30: =Assumptions!$C$25 -> 4200 | D30: =Assumptions!$C$25 -> 4200 | E30: =Assumptions!$C$25 -> 4200 | F30: =Assumptions!$C$25 -> 4200 | G30: =Assumptions!$C$25 -> 4200 | H30: =Assumptions!$C$25 -> 4200 | I30: =Assumptions!$C$25 -> 4200 | J30: =Assumptions!$C$25 -> 4200 | ... N30: =Assumptions!$C$25 -> 4200 | O30: =SUM(C30:N30) -> 50400
A31: Other G&A | B31: £ | C31: =Assumptions!$C$26 -> 6000 | D31: =Assumptions!$C$26 -> 6000 | E31: =Assumptions!$C$26 -> 6000 | F31: =Assumptions!$C$26 -> 6000 | G31: =Assumptions!$C$26 -> 6000 | H31: =Assumptions!$C$26 -> 6000 | I31: =Assumptions!$C$26 -> 6000 | J31: =Assumptions!$C$26 -> 6000 | ... N31: =Assumptions!$C$26 -> 6000 | O31: =SUM(C31:N31) -> 72000
A32: Total operating expenses | B32: £ | C32: =C26+C27+C28+C29+C30+C31 -> 164100 | D32: =D26+D27+D28+D29+D30+D31 -> 164720 | E32: =E26+E27+E28+E29+E30+E31 -> 170013.33 | F32: =F26+F27+F28+F29+F30+F31 -> 170633.33 | G32: =G26+G27+G28+G29+G30+G31 -> 170633.33 | H32: =H26+H27+H28+H29+H30+H31 -> 176546.67 | I32: =I26+I27+I28+I29+I30+I31 -> 177166.67 | J32: =J26+J27+J28+J29+J30+J31 -> 177166.67 | ... N32: =N26+N27+N28+N29+N30+N31 -> 189613.33 | O32: =SUM(C32:N32) -> 2115746.7
A33: EBITDA | B33: £ | C33: =C21-C32 -> -31568.5 | D33: =D21-D32 -> -26018.575 | E33: =E21-E32 -> -25445.558 | F33: =F21-F32 -> -19755.958 | G33: =G21-G32 -> -13889.608 | H33: =H21-H32 -> -13353.667 | I33: =I21-I32 -> -581.51867 | J33: =J21-J32 -> 5832.8893 | ... N33: =N21-N32 -> 20810.951 | O33: =SUM(C33:N33) -> -69718.981
A34: EBITDA margin % | B34: % | C34: =IFERROR(C33/C16,0) -> -0.2163708 | D34: =IFERROR(D33/D16,0) -> -0.17038457 | E34: =IFERROR(E33/E16,0) -> -0.15981885 | F34: =IFERROR(F33/F16,0) -> -0.11888647 | G34: =IFERROR(G33/G16,0) -> -0.080433207 | H34: =IFERROR(H33/H16,0) -> -0.074269559 | I34: =IFERROR(I33/I16,0) -> -0.0029978774 | J34: =IFERROR(J33/J16,0) -> 0.029009305 | ... O34: =IFERROR(O33/O16,0) -> -0.030978949
A35: Depreciation | B35: £ | C35: =Assumptions!$C$30+Assumptions!$C$28*(C6-1)/Assumptions!$C$29 -> 4500 | D35: =Assumptions!$C$30+Assumptions!$C$28*(D6-1)/Assumptions!$C$29 -> 4722.2222 | E35: =Assumptions!$C$30+Assumptions!$C$28*(E6-1)/Assumptions!$C$29 -> 4944.4444 | F35: =Assumptions!$C$30+Assumptions!$C$28*(F6-1)/Assumptions!$C$29 -> 5166.6667 | G35: =Assumptions!$C$30+Assumptions!$C$28*(G6-1)/Assumptions!$C$29 -> 5388.8889 | H35: =Assumptions!$C$30+Assumptions!$C$28*(H6-1)/Assumptions!$C$29 -> 5611.1111 | I35: =Assumptions!$C$30+Assumptions!$C$28*(I6-1)/Assumptions!$C$29 -> 5833.3333 | J35: =Assumptions!$C$30+Assumptions!$C$28*(J6-1)/Assumptions!$C$29 -> 6055.5556 | ... N35: =Assumptions!$C$30+Assumptions!$C$28*(N6-1)/Assumptions!$C$29 -> 6944.4444 | O35: =SUM(C35:N35) -> 68666.667
A36: EBIT | B36: £ | C36: =C33-C35 -> -36068.5 | D36: =D33-D35 -> -30740.797 | E36: =E33-E35 -> -30390.003 | F36: =F33-F35 -> -24922.625 | G36: =G33-G35 -> -19278.497 | H36: =H33-H35 -> -18964.778 | I36: =I33-I35 -> -6414.852 | J36: =J33-J35 -> -222.66622 | ... N36: =N33-N35 -> 13866.506 | O36: =SUM(C36:N36) -> -138385.65
A37: Corporation tax charge | B37: £ | C37: =MAX(0,C36)*Assumptions!$C$31 -> 0 | D37: =MAX(0,D36)*Assumptions!$C$31 -> 0 | E37: =MAX(0,E36)*Assumptions!$C$31 -> 0 | F37: =MAX(0,F36)*Assumptions!$C$31 -> 0 | G37: =MAX(0,G36)*Assumptions!$C$31 -> 0 | H37: =MAX(0,H36)*Assumptions!$C$31 -> 0 | I37: =MAX(0,I36)*Assumptions!$C$31 -> 0 | J37: =MAX(0,J36)*Assumptions!$C$31 -> 0 | ... N37: =MAX(0,N36)*Assumptions!$C$31 -> 3466.6266 | O37: =SUM(C37:N37) -> 7154.2677
A38: Net income | B38: £ | C38: =C36-C37 -> -36068.5 | D38: =D36-D37 -> -30740.797 | E38: =E36-E37 -> -30390.003 | F38: =F36-F37 -> -24922.625 | G38: =G36-G37 -> -19278.497 | H38: =H36-H37 -> -18964.778 | I38: =I36-I37 -> -6414.852 | J38: =J36-J37 -> -222.66622 | ... N38: =N36-N37 -> 10399.88 | O38: =SUM(C38:N38) -> -145539.92
A39: CASH FLOW
A40: Cash received from customers | B40: £ | C40: =C16*Assumptions!$C$32+Assumptions!$C$34 -> 140720 | D40: =D16*Assumptions!$C$32+C16*(1-Assumptions!$C$32) -> 151344 | E40: =E16*Assumptions!$C$32+D16*(1-Assumptions!$C$32) -> 157913 | F40: =F16*Assumptions!$C$32+E16*(1-Assumptions!$C$32) -> 164783 | G40: =G16*Assumptions!$C$32+F16*(1-Assumptions!$C$32) -> 171383 | H40: =H16*Assumptions!$C$32+G16*(1-Assumptions!$C$32) -> 178377 | I40: =I16*Assumptions!$C$32+H16*(1-Assumptions!$C$32) -> 191141.44 | J40: =J16*Assumptions!$C$32+I16*(1-Assumptions!$C$32) -> 199651.04 | K40: =K16*Assumptions!$C$32+J16*(1-Assumptions!$C$32) -> 207103.84 | ... N40: =N16*Assumptions!$C$32+M16*(1-Assumptions!$C$32) -> 229701.36 | O40: =SUM(C40:N40) -> 2228272.7
A41: Cost of sales paid | B41: £ | C41: =C20 -> 13368.5 | D41: =D20 -> 14003.575 | E41: =E20 -> 14647.225 | F41: =F20 -> 15297.625 | G41: =G20 -> 15941.275 | H41: =H20 -> 16607 | I41: =I20 -> 17391.652 | J41: =J20 -> 18070.044 | ... N41: =N20 -> 20850.116 | O41: =SUM(C41:N41) -> 204499.91
...

Sheet Model_Upside
A1: Upside case: monthly model
A2: Driven by the 'Upside' column of Assumptions. Same layout on all three scenario sheets and on Budget_Locked.
A4: £ unless stated | B4: Unit | C4: Apr-26 | D4: May-26 | E4: Jun-26 | F4: Jul-26 | G4: Aug-26 | H4: Sep-26 | I4: Oct-26 | J4: Nov-26 | K4: Dec-26 | L4: Jan-27 | M4: Feb-27 | N4: Mar-27 | O4: FY 2026/27
A5: CUSTOMERS
A6: Month number | B6: # | C6: 1 | D6: 2 | E6: 3 | F6: 4 | G6: 5 | H6: 6 | I6: 7 | J6: 8 | K6: 9 | L6: 10 | M6: 11 | N6: 12
A7: Opening customers | B7: customers | C7: =Assumptions!$D$6 -> 420 | D7: =C10 -> 448 | E7: =D10 -> 477 | F7: =E10 -> 506 | G7: =F10 -> 536 | H7: =G10 -> 566 | I7: =H10 -> 597 | J7: =I10 -> 630 | K7: =J10 -> 663 | ... N7: =M10 -> 767 | O7: =C7 -> 420
A8: New customers | B8: customers | C8: =ROUND(Assumptions!$D$7*(1+Assumptions!$D$8)^(C6-1),0) -> 34 | D8: =ROUND(Assumptions!$D$7*(1+Assumptions!$D$8)^(D6-1),0) -> 35 | E8: =ROUND(Assumptions!$D$7*(1+Assumptions!$D$8)^(E6-1),0) -> 36 | F8: =ROUND(Assumptions!$D$7*(1+Assumptions!$D$8)^(F6-1),0) -> 37 | G8: =ROUND(Assumptions!$D$7*(1+Assumptions!$D$8)^(G6-1),0) -> 38 | H8: =ROUND(Assumptions!$D$7*(1+Assumptions!$D$8)^(H6-1),0) -> 39 | I8: =ROUND(Assumptions!$D$7*(1+Assumptions!$D$8)^(I6-1),0) -> 41 | J8: =ROUND(Assumptions!$D$7*(1+Assumptions!$D$8)^(J6-1),0) -> 42 | ... N8: =ROUND(Assumptions!$D$7*(1+Assumptions!$D$8)^(N6-1),0) -> 47 | O8: =SUM(C8:N8) -> 482
A9: Churned customers | B9: customers | C9: =ROUND(C7*Assumptions!$D$9,0) -> 6 | D9: =ROUND(D7*Assumptions!$D$9,0) -> 6 | E9: =ROUND(E7*Assumptions!$D$9,0) -> 7 | F9: =ROUND(F7*Assumptions!$D$9,0) -> 7 | G9: =ROUND(G7*Assumptions!$D$9,0) -> 8 | H9: =ROUND(H7*Assumptions!$D$9,0) -> 8 | I9: =ROUND(I7*Assumptions!$D$9,0) -> 8 | J9: =ROUND(J7*Assumptions!$D$9,0) -> 9 | ... N9: =ROUND(N7*Assumptions!$D$9,0) -> 11 | O9: =SUM(C9:N9) -> 99
A10: Closing customers | B10: customers | C10: =C7+C8-C9 -> 448 | D10: =D7+D8-D9 -> 477 | E10: =E7+E8-E9 -> 506 | F10: =F7+F8-F9 -> 536 | G10: =G7+G8-G9 -> 566 | H10: =H7+H8-H9 -> 597 | I10: =I7+I8-I9 -> 630 | J10: =J7+J8-J9 -> 663 | ... N10: =N7+N8-N9 -> 803 | O10: =N10 -> 803
A11: Average customers | B11: customers | C11: =(C7+C10)/2 -> 434 | D11: =(D7+D10)/2 -> 462.5 | E11: =(E7+E10)/2 -> 491.5 | F11: =(F7+F10)/2 -> 521 | G11: =(G7+G10)/2 -> 551 | H11: =(H7+H10)/2 -> 581.5 | I11: =(I7+I10)/2 -> 613.5 | J11: =(J7+J10)/2 -> 646.5 | ... N11: =(N7+N10)/2 -> 785 | O11: =AVERAGE(C11:N11) -> 602.45833
A12: ARPA (after price increase) | B12: £ / month | C12: =Assumptions!$D$10*IF(C6>=Assumptions!$D$12,1+Assumptions!$D$11,1) -> 322 | D12: =Assumptions!$D$10*IF(D6>=Assumptions!$D$12,1+Assumptions!$D$11,1) -> 322 | E12: =Assumptions!$D$10*IF(E6>=Assumptions!$D$12,1+Assumptions!$D$11,1) -> 322 | F12: =Assumptions!$D$10*IF(F6>=Assumptions!$D$12,1+Assumptions!$D$11,1) -> 322 | G12: =Assumptions!$D$10*IF(G6>=Assumptions!$D$12,1+Assumptions!$D$11,1) -> 322 | H12: =Assumptions!$D$10*IF(H6>=Assumptions!$D$12,1+Assumptions!$D$11,1) -> 322 | I12: =Assumptions!$D$10*IF(I6>=Assumptions!$D$12,1+Assumptions!$D$11,1) -> 338.1 | J12: =Assumptions!$D$10*IF(J6>=Assumptions!$D$12,1+Assumptions!$D$11,1) -> 338.1 | ... N12: =Assumptions!$D$10*IF(N6>=Assumptions!$D$12,1+Assumptions!$D$11,1) -> 338.1 | O12: =AVERAGE(C12:N12) -> 330.05
A13: PROFIT AND LOSS
A14: Subscription revenue | B14: £ | C14: =C11*C12 -> 139748 | D14: =D11*D12 -> 148925 | E14: =E11*E12 -> 158263 | F14: =F11*F12 -> 167762 | G14: =G11*G12 -> 177422 | H14: =H11*H12 -> 187243 | I14: =I11*I12 -> 207424.35 | J14: =J11*J12 -> 218581.65 | ... N14: =N11*N12 -> 265408.5 | O14: =SUM(C14:N14) -> 2395325.8
A15: Onboarding revenue | B15: £ | C15: =C8*Assumptions!$D$13 -> 15300 | D15: =D8*Assumptions!$D$13 -> 15750 | E15: =E8*Assumptions!$D$13 -> 16200 | F15: =F8*Assumptions!$D$13 -> 16650 | G15: =G8*Assumptions!$D$13 -> 17100 | H15: =H8*Assumptions!$D$13 -> 17550 | I15: =I8*Assumptions!$D$13 -> 18450 | J15: =J8*Assumptions!$D$13 -> 18900 | ... N15: =N8*Assumptions!$D$13 -> 21150 | O15: =SUM(C15:N15) -> 216900
A16: Total revenue | B16: £ | C16: =C14+C15 -> 155048 | D16: =D14+D15 -> 164675 | E16: =E14+E15 -> 174463 | F16: =F14+F15 -> 184412 | G16: =G14+G15 -> 194522 | H16: =H14+H15 -> 204793 | I16: =I14+I15 -> 225874.35 | J16: =J14+J15 -> 237481.65 | ... N16: =N14+N15 -> 286558.5 | O16: =SUM(C16:N16) -> 2612225.8
A17: Hosting | B17: £ | C17: =C11*Assumptions!$D$15 -> 6076 | D17: =D11*Assumptions!$D$15 -> 6475 | E17: =E11*Assumptions!$D$15 -> 6881 | F17: =F11*Assumptions!$D$15 -> 7294 | G17: =G11*Assumptions!$D$15 -> 7714 | H17: =H11*Assumptions!$D$15 -> 8141 | I17: =I11*Assumptions!$D$15 -> 8589 | J17: =J11*Assumptions!$D$15 -> 9051 | ... N17: =N11*Assumptions!$D$15 -> 10990 | O17: =SUM(C17:N17) -> 101213
A18: Customer support | B18: £ | C18: =C11*Assumptions!$D$16 -> 5208 | D18: =D11*Assumptions!$D$16 -> 5550 | E18: =E11*Assumptions!$D$16 -> 5898 | F18: =F11*Assumptions!$D$16 -> 6252 | G18: =G11*Assumptions!$D$16 -> 6612 | H18: =H11*Assumptions!$D$16 -> 6978 | I18: =I11*Assumptions!$D$16 -> 7362 | J18: =J11*Assumptions!$D$16 -> 7758 | ... N18: =N11*Assumptions!$D$16 -> 9420 | O18: =SUM(C18:N18) -> 86754
A19: Payment fees | B19: £ | C19: =C16*Assumptions!$D$17 -> 2325.72 | D19: =D16*Assumptions!$D$17 -> 2470.125 | E19: =E16*Assumptions!$D$17 -> 2616.945 | F19: =F16*Assumptions!$D$17 -> 2766.18 | G19: =G16*Assumptions!$D$17 -> 2917.83 | H19: =H16*Assumptions!$D$17 -> 3071.895 | I19: =I16*Assumptions!$D$17 -> 3388.1152 | J19: =J16*Assumptions!$D$17 -> 3562.2248 | ... N19: =N16*Assumptions!$D$17 -> 4298.3775 | O19: =SUM(C19:N19) -> 39183.387
A20: Total cost of sales | B20: £ | C20: =C17+C18+C19 -> 13609.72 | D20: =D17+D18+D19 -> 14495.125 | E20: =E17+E18+E19 -> 15395.945 | F20: =F17+F18+F19 -> 16312.18 | G20: =G17+G18+G19 -> 17243.83 | H20: =H17+H18+H19 -> 18190.895 | I20: =I17+I18+I19 -> 19339.115 | J20: =J17+J18+J19 -> 20371.225 | ... N20: =N17+N18+N19 -> 24708.377 | O20: =SUM(C20:N20) -> 227150.39
A21: Gross profit | B21: £ | C21: =C16-C20 -> 141438.28 | D21: =D16-D20 -> 150179.88 | E21: =E16-E20 -> 159067.05 | F21: =F16-F20 -> 168099.82 | G21: =G16-G20 -> 177278.17 | H21: =H16-H20 -> 186602.11 | I21: =I16-I20 -> 206535.23 | J21: =J16-J20 -> 217110.43 | ... N21: =N16-N20 -> 261850.12 | O21: =SUM(C21:N21) -> 2385075.4
A22: Gross margin % | B22: % | C22: =IFERROR(C21/C16,0) -> 0.91222254 | D22: =IFERROR(D21/D16,0) -> 0.91197738 | E22: =IFERROR(E21/E16,0) -> 0.91175238 | F22: =IFERROR(F21/F16,0) -> 0.91154491 | G22: =IFERROR(G21/G16,0) -> 0.9113528 | H22: =IFERROR(H21/H16,0) -> 0.91117423 | I22: =IFERROR(I21/I16,0) -> 0.91438109 | J22: =IFERROR(J21/J16,0) -> 0.91421979 | ... O22: =IFERROR(O21/O16,0) -> 0.91304336
A23: Opening headcount | B23: FTE | C23: =Assumptions!$D$19 -> 24 | D23: =C25 -> 24 | E23: =D25 -> 25 | F23: =E25 -> 26 | G23: =F25 -> 26 | H23: =G25 -> 27 | I23: =H25 -> 28 | J23: =I25 -> 28 | K23: =J25 -> 29 | ... N23: =M25 -> 31 | O23: =C23 -> 24
A24: New hires | B24: FTE | C24: =Assumptions!C40 -> 0 | D24: =Assumptions!D40 -> 1 | E24: =Assumptions!E40 -> 1 | F24: =Assumptions!F40 -> 0 | G24: =Assumptions!G40 -> 1 | H24: =Assumptions!H40 -> 1 | I24: =Assumptions!I40 -> 0 | J24: =Assumptions!J40 -> 1 | ... N24: =Assumptions!N40 -> 0 | O24: =SUM(C24:N24) -> 7
A25: Closing headcount | B25: FTE | C25: =C23+C24 -> 24 | D25: =D23+D24 -> 25 | E25: =E23+E24 -> 26 | F25: =F23+F24 -> 26 | G25: =G23+G24 -> 27 | H25: =H23+H24 -> 28 | I25: =I23+I24 -> 28 | J25: =J23+J24 -> 29 | ... N25: =N23+N24 -> 31 | O25: =N25 -> 31
A26: Salaries and on-costs | B26: £ | C26: =C25*Assumptions!$D$20/12*(1+Assumptions!$D$21) -> 122720 | D26: =D25*Assumptions!$D$20/12*(1+Assumptions!$D$21) -> 127833.33 | E26: =E25*Assumptions!$D$20/12*(1+Assumptions!$D$21) -> 132946.67 | F26: =F25*Assumptions!$D$20/12*(1+Assumptions!$D$21) -> 132946.67 | G26: =G25*Assumptions!$D$20/12*(1+Assumptions!$D$21) -> 138060 | H26: =H25*Assumptions!$D$20/12*(1+Assumptions!$D$21) -> 143173.33 | I26: =I25*Assumptions!$D$20/12*(1+Assumptions!$D$21) -> 143173.33 | J26: =J25*Assumptions!$D$20/12*(1+Assumptions!$D$21) -> 148286.67 | ... N26: =N25*Assumptions!$D$20/12*(1+Assumptions!$D$21) -> 158513.33 | O26: =SUM(C26:N26) -> 1712966.7
A27: Marketing (CAC x new customers) | B27: £ | C27: =C8*Assumptions!$D$22 -> 19720 | D27: =D8*Assumptions!$D$22 -> 20300 | E27: =E8*Assumptions!$D$22 -> 20880 | F27: =F8*Assumptions!$D$22 -> 21460 | G27: =G8*Assumptions!$D$22 -> 22040 | H27: =H8*Assumptions!$D$22 -> 22620 | I27: =I8*Assumptions!$D$22 -> 23780 | J27: =J8*Assumptions!$D$22 -> 24360 | ... N27: =N8*Assumptions!$D$22 -> 27260 | O27: =SUM(C27:N27) -> 279560
A28: Software and tools | B28: £ | C28: =C25*Assumptions!$D$23 -> 4320 | D28: =D25*Assumptions!$D$23 -> 4500 | E28: =E25*Assumptions!$D$23 -> 4680 | F28: =F25*Assumptions!$D$23 -> 4680 | G28: =G25*Assumptions!$D$23 -> 4860 | H28: =H25*Assumptions!$D$23 -> 5040 | I28: =I25*Assumptions!$D$23 -> 5040 | J28: =J25*Assumptions!$D$23 -> 5220 | ... N28: =N25*Assumptions!$D$23 -> 5580 | O28: =SUM(C28:N28) -> 60300
A29: Rent and facilities | B29: £ | C29: =Assumptions!$D$24 -> 9500 | D29: =Assumptions!$D$24 -> 9500 | E29: =Assumptions!$D$24 -> 9500 | F29: =Assumptions!$D$24 -> 9500 | G29: =Assumptions!$D$24 -> 9500 | H29: =Assumptions!$D$24 -> 9500 | I29: =Assumptions!$D$24 -> 9500 | J29: =Assumptions!$D$24 -> 9500 | ... N29: =Assumptions!$D$24 -> 9500 | O29: =SUM(C29:N29) -> 114000
A30: Professional fees | B30: £ | C30: =Assumptions!$D$25 -> 4200 | D30: =Assumptions!$D$25 -> 4200 | E30: =Assumptions!$D$25 -> 4200 | F30: =Assumptions!$D$25 -> 4200 | G30: =Assumptions!$D$25 -> 4200 | H30: =Assumptions!$D$25 -> 4200 | I30: =Assumptions!$D$25 -> 4200 | J30: =Assumptions!$D$25 -> 4200 | ... N30: =Assumptions!$D$25 -> 4200 | O30: =SUM(C30:N30) -> 50400
A31: Other G&A | B31: £ | C31: =Assumptions!$D$26 -> 6000 | D31: =Assumptions!$D$26 -> 6000 | E31: =Assumptions!$D$26 -> 6000 | F31: =Assumptions!$D$26 -> 6000 | G31: =Assumptions!$D$26 -> 6000 | H31: =Assumptions!$D$26 -> 6000 | I31: =Assumptions!$D$26 -> 6000 | J31: =Assumptions!$D$26 -> 6000 | ... N31: =Assumptions!$D$26 -> 6000 | O31: =SUM(C31:N31) -> 72000
A32: Total operating expenses | B32: £ | C32: =C26+C27+C28+C29+C30+C31 -> 166460 | D32: =D26+D27+D28+D29+D30+D31 -> 172333.33 | E32: =E26+E27+E28+E29+E30+E31 -> 178206.67 | F32: =F26+F27+F28+F29+F30+F31 -> 178786.67 | G32: =G26+G27+G28+G29+G30+G31 -> 184660 | H32: =H26+H27+H28+H29+H30+H31 -> 190533.33 | I32: =I26+I27+I28+I29+I30+I31 -> 191693.33 | J32: =J26+J27+J28+J29+J30+J31 -> 197566.67 | ... N32: =N26+N27+N28+N29+N30+N31 -> 211053.33 | O32: =SUM(C32:N32) -> 2289226.7
A33: EBITDA | B33: £ | C33: =C21-C32 -> -25021.72 | D33: =D21-D32 -> -22153.458 | E33: =E21-E32 -> -19139.612 | F33: =F21-F32 -> -10686.847 | G33: =G21-G32 -> -7381.83 | H33: =H21-H32 -> -3931.2283 | I33: =I21-I32 -> 14841.901 | J33: =J21-J32 -> 19543.759 | ... N33: =N21-N32 -> 50796.789 | O33: =SUM(C33:N33) -> 95848.746
A34: EBITDA margin % | B34: % | C34: =IFERROR(C33/C16,0) -> -0.16138048 | D34: =IFERROR(D33/D16,0) -> -0.13452836 | E34: =IFERROR(E33/E16,0) -> -0.10970585 | F34: =IFERROR(F33/F16,0) -> -0.057950929 | G34: =IFERROR(G33/G16,0) -> -0.037948561 | H34: =IFERROR(H33/H16,0) -> -0.019196107 | I34: =IFERROR(I33/I16,0) -> 0.065708662 | J34: =IFERROR(J33/J16,0) -> 0.082295868 | ... O34: =IFERROR(O33/O16,0) -> 0.036692366
A35: Depreciation | B35: £ | C35: =Assumptions!$D$30+Assumptions!$D$28*(C6-1)/Assumptions!$D$29 -> 4500 | D35: =Assumptions!$D$30+Assumptions!$D$28*(D6-1)/Assumptions!$D$29 -> 4722.2222 | E35: =Assumptions!$D$30+Assumptions!$D$28*(E6-1)/Assumptions!$D$29 -> 4944.4444 | F35: =Assumptions!$D$30+Assumptions!$D$28*(F6-1)/Assumptions!$D$29 -> 5166.6667 | G35: =Assumptions!$D$30+Assumptions!$D$28*(G6-1)/Assumptions!$D$29 -> 5388.8889 | H35: =Assumptions!$D$30+Assumptions!$D$28*(H6-1)/Assumptions!$D$29 -> 5611.1111 | I35: =Assumptions!$D$30+Assumptions!$D$28*(I6-1)/Assumptions!$D$29 -> 5833.3333 | J35: =Assumptions!$D$30+Assumptions!$D$28*(J6-1)/Assumptions!$D$29 -> 6055.5556 | ... N35: =Assumptions!$D$30+Assumptions!$D$28*(N6-1)/Assumptions!$D$29 -> 6944.4444 | O35: =SUM(C35:N35) -> 68666.667
